#X-Generator: crowdin.com
# Content-related messages

content.content_missing=\ub178\ub4dc\uc758 \ucf58\ud150\uce20\uac00 \ub204\ub77d\:\n \ub178\ub4dc\: {0}\n \ub9ac\ub354\: {1}\n \uc2dc\uc2a4\ud15c \uad00\ub9ac\uc790\uc5d0\uac8c \ubb38\uc758\ud558\uc138\uc694.
content.runtime_exec.property_moved=The property ''errorCodes'' has moved down onto the RuntimeExec class

index.recovery.out_of_date=\uc778\ub371\uc2a4\uac00 \ub370\uc774\ud130\ubca0\uc774\uc2a4\uc640 \ub3d9\uae30\ud654 \ub418\uc9c0 \uc54a\uc2b5\ub2c8\ub2e4.
index.tracking.starting=\uc0c9\uc778 \ubcf5\uad6c \uc2dc\uc791.
index.tracking.complete=\uc0c9\uc778 \ubcf5\uad6c \uc644\ub8cc.
index.tracking.progress=\ {0}\uad00\ub828 \ud2b8\ub79c\uc7ad\uc158 \ucc98\ub9ac.
index.recovery.starting=\uc0c9\uc778 \ubcf5\uad6c \uc2dc\uc791 \: {0} \ud2b8\ub80c\uc81d\uc158.
index.recovery.complete=\uc0c9\uc778 \ubcf5\uad6c \uc644\ub8cc.
index.recovery.progress=\ {0} % \uc644\ub8cc.
index.recovery.terminated=\uc0c9\uc778 \ubcf5\uad6c\uac00 \uc911\ub2e8\ub428.

node.archive.msg.busy=A bulk purge or restore operation is currently in progress

content.http_reader.err.no_connection=Unable to connect to remote Alfresco server via HTTP\: {0}
content.http_reader.err.no_authentication=The HTTP reader was unable to authenticate on the remote server\: {0}  \n
content.http_reader.err.check_cluster=Please ensure that ''replicateUpdates'' and ''replicateUpdatesViaCopy'' is enabled for the cache ''org.alfresco.cache.ticketsCache''.  Check that the general cluster configuration is correct and working.
content.http_reader.err.unrecognized=An unrecognized error occurred when attempting to download content from remote server\:\n   Server\: {0} \n   Content\: {1} \n   HTTP Response\: {2}

metadata.extraction.err.type_conversion=Metadata extraction failed because an extracted value failed to convert to the required type\: \n   Extractor\: {0} \n   Target Property QName\: {1} \n   Required Type\: {2} \n   Extracted Value\: {3}

transform.err.format_or_password=Failed to convert content, possibly due to an incorrectly formatted or password protected file.

content.routing.err.invalid_default_store=The ''defaultStoreName'', ''{0}'' does not refer to a store in ''storesByName'' ({1}).
