#X-Generator: crowdin.com
# Content-related messages

content.content_missing=O conte\u00fado do n\u00f3 est\u00e1 em falta\: \n   n\u00f3\: {0} \n   leitor\: {1}  \n   Contacte o seu administrador de sistema.
content.runtime_exec.property_moved=A propriedade ''errorCodes'' foi movida para a classe RuntimeExec

index.recovery.out_of_date=Os \u00edndices n\u00e3o est\u00e3o sincronizados com a base de dados.
index.tracking.starting=Recupera\u00e7\u00e3o de \u00cdndices iniciada.
index.tracking.complete=Recupera\u00e7\u00e3o de \u00cdndices conclu\u00edda.
index.tracking.progress=A processar transac\u00e7\u00f5es \u00e0 volta de {0}.
index.recovery.starting=Recupera\u00e7\u00e3o de \u00cdndices iniciada\: {0} transac\u00e7\u00f5es.
index.recovery.complete=Recupera\u00e7\u00e3o de \u00cdndices conclu\u00edda.
index.recovery.progress={0} % conclu\u00eddo.
index.recovery.terminated=Recupera\u00e7\u00e3o de \u00cdndices terminada.

node.archive.msg.busy=A remo\u00e7\u00e3o em lote ou opera\u00e7\u00e3o de restauro est\u00e1 em progresso.

content.http_reader.err.no_connection=N\u00e3o foi poss\u00edvel conectar ao servidor remoto de Alfresco via HTTP\: {0}
content.http_reader.err.no_authentication=O leitor HTTP n\u00e3o se conseguiu autenticar no servidor remoto\: {0} \n
content.http_reader.err.check_cluster=Por favor, verifique se ''replicateUpdates'' e ''replicateUpdatesViaCopy'' est\u00e3o activados para a cache ''org.alfresco.cache.ticketsCache''. Verifique se a configura\u00e7\u00e3o do cluster est\u00e1 correcta e a funcionar.
content.http_reader.err.unrecognized=Ocorreu um erro desconhecido ao tentar fazer download de conte\u00fado atrav\u00e9s do servidor remoto\:\n Servidor\: {0} Conte\u00fado\: {1} \n Resposta HTTP\: {2}

metadata.extraction.err.type_conversion=A extra\u00e7\u00e3o de metadados falhou porque n\u00e3o foi poss\u00edvel converter um dos valores extra\u00eddos para o tipo respectivo\: \n Extrator\: {0} \n   Nome da Propriedade Destino\: {1} \n   Tipo Necess\u00e1rio\: {2} \n   Valor Extra\u00eddo\: {3}

transform.err.format_or_password=Falha ao converter conte\u00fado, possivelmente devido a um ficheiro formatado incorretamente ou protegido por senha.

content.routing.err.invalid_default_store=O ''defaultStoreName'',''{0}'' n\u00e3o se refere a um arquivo em ''storesByName "({1}).
